2021-12-04 23:36:14,398 INFO    MainThread:15236 [wandb_setup.py:_flush():71] setting env: {}
2021-12-04 23:36:14,398 INFO    MainThread:15236 [wandb_setup.py:_flush():71] setting login settings: {'anonymous': 'must'}
2021-12-04 23:36:14,398 INFO    MainThread:15236 [wandb_init.py:_log_setup():371] Logging user logs to D:\Pytorch-UNet-master\wandb\run-20211204_233614-1amkgcb3\logs\debug.log
2021-12-04 23:36:14,398 INFO    MainThread:15236 [wandb_init.py:_log_setup():372] Logging internal logs to D:\Pytorch-UNet-master\wandb\run-20211204_233614-1amkgcb3\logs\debug-internal.log
2021-12-04 23:36:14,398 INFO    MainThread:15236 [wandb_init.py:init():404] calling init triggers
2021-12-04 23:36:14,398 INFO    MainThread:15236 [wandb_init.py:init():411] wandb.init called with sweep_config: {}
config: {}
2021-12-04 23:36:14,398 INFO    MainThread:15236 [wandb_init.py:init():449] starting backend
2021-12-04 23:36:14,398 INFO    MainThread:15236 [backend.py:_multiprocessing_setup():97] multiprocessing start_methods=spawn, using: spawn
2021-12-04 23:36:14,414 INFO    MainThread:15236 [backend.py:ensure_launched():199] starting backend process...
2021-12-04 23:36:16,620 INFO    MainThread:15236 [backend.py:ensure_launched():205] started backend process with pid: 32884
2021-12-04 23:36:16,620 INFO    MainThread:15236 [wandb_init.py:init():458] backend started and connected
2021-12-04 23:36:16,636 INFO    MainThread:15236 [wandb_init.py:init():519] updated telemetry
2021-12-04 23:36:16,636 INFO    MainThread:15236 [wandb_init.py:init():549] communicating current version
2021-12-04 23:36:18,260 INFO    MainThread:15236 [wandb_init.py:init():554] got version response 
2021-12-04 23:36:18,260 INFO    MainThread:15236 [wandb_init.py:init():564] communicating run to backend with 30 second timeout
2021-12-04 23:36:48,271 INFO    MainThread:15236 [interface_queue.py:_communicate_run():336] couldn't get run from backend
2021-12-04 23:36:48,271 ERROR   MainThread:15236 [wandb_init.py:init():569] backend process timed out
2021-12-04 23:36:48,271 ERROR   MainThread:15236 [wandb_init.py:init():578] encountered error: Error communicating with wandb process
try: wandb.init(settings=wandb.Settings(start_method='fork'))
or:  wandb.init(settings=wandb.Settings(start_method='thread'))
For more info see: https://docs.wandb.ai/library/init#init-start-error
